<?xml version="1.0" encoding="UTF-8"?>
<!-- Generated by org.testng.reporters.JUnitReportReporter -->
<testsuite hostname="DESKTOP-C2GS8GR" name="testcase.Demo" tests="2" failures="1" timestamp="12 Oct 2022 05:28:38 GMT" time="0.040" errors="1">
  <testcase name="parentTest" time="0.040" classname="testcase.Demo">
    <failure type="java.lang.AssertionError" message="expected [value] but found [hello]">
      <![CDATA[java.lang.AssertionError: expected [value] but found [hello]
	at org.testng.Assert.fail(Assert.java:94)
	at org.testng.Assert.failNotEquals(Assert.java:496)
	at org.testng.Assert.assertEquals(Assert.java:125)
	at org.testng.Assert.assertEquals(Assert.java:178)
	at org.testng.Assert.assertEquals(Assert.java:188)
	at testcase.Demo.parentTest(Demo.java:14)
	at sun.reflect.NativeMethodAccessorImpl.invoke0(Native Method)
	at sun.reflect.NativeMethodAccessorImpl.invoke(Unknown Source)
	at sun.reflect.DelegatingMethodAccessorImpl.invoke(Unknown Source)
	at java.lang.reflect.Method.invoke(Unknown Source)
	at org.testng.internal.MethodInvocationHelper.invokeMethod(MethodInvocationHelper.java:85)
	at org.testng.internal.Invoker.invokeMethod(Invoker.java:639)
	at org.testng.internal.Invoker.invokeTestMethod(Invoker.java:816)
	at org.testng.internal.Invoker.invokeTestMethods(Invoker.java:1124)
	at org.testng.internal.TestMethodWorker.invokeTestMethods(TestMethodWorker.java:125)
	at org.testng.internal.TestMethodWorker.run(TestMethodWorker.java:108)
	at org.testng.TestRunner.privateRun(TestRunner.java:774)
	at org.testng.TestRunner.run(TestRunner.java:624)
	at org.testng.SuiteRunner.runTest(SuiteRunner.java:359)
	at org.testng.SuiteRunner.runSequentially(SuiteRunner.java:354)
	at org.testng.SuiteRunner.privateRun(SuiteRunner.java:312)
	at org.testng.SuiteRunner.run(SuiteRunner.java:261)
	at org.testng.SuiteRunnerWorker.runSuite(SuiteRunnerWorker.java:52)
	at org.testng.SuiteRunnerWorker.run(SuiteRunnerWorker.java:86)
	at org.testng.TestNG.runSuitesSequentially(TestNG.java:1191)
	at org.testng.TestNG.runSuitesLocally(TestNG.java:1116)
	at org.testng.TestNG.run(TestNG.java:1024)
	at org.testng.remote.RemoteTestNG.run(RemoteTestNG.java:112)
	at org.testng.remote.RemoteTestNG.initAndRun(RemoteTestNG.java:205)
	at org.testng.remote.RemoteTestNG.main(RemoteTestNG.java:176)
]]>
    </failure>
  </testcase> <!-- parentTest -->
  <testcase name="dependentTest" time="0.000" classname="testcase.Demo">
    <error type="java.lang.Throwable" message="Method Demo.dependentTest()[pri:0, instance:testcase.Demo@56cbfb61] depends on not successfully finished methods">
      <![CDATA[java.lang.Throwable: Method Demo.dependentTest()[pri:0, instance:testcase.Demo@56cbfb61] depends on not successfully finished methods
	at org.testng.internal.Invoker.invokeTestMethods(Invoker.java:1033)
	at org.testng.internal.TestMethodWorker.invokeTestMethods(TestMethodWorker.java:125)
	at org.testng.internal.TestMethodWorker.run(TestMethodWorker.java:108)
	at org.testng.TestRunner.privateRun(TestRunner.java:774)
	at org.testng.TestRunner.run(TestRunner.java:624)
	at org.testng.SuiteRunner.runTest(SuiteRunner.java:359)
	at org.testng.SuiteRunner.runSequentially(SuiteRunner.java:354)
	at org.testng.SuiteRunner.privateRun(SuiteRunner.java:312)
	at org.testng.SuiteRunner.run(SuiteRunner.java:261)
	at org.testng.SuiteRunnerWorker.runSuite(SuiteRunnerWorker.java:52)
	at org.testng.SuiteRunnerWorker.run(SuiteRunnerWorker.java:86)
	at org.testng.TestNG.runSuitesSequentially(TestNG.java:1191)
	at org.testng.TestNG.runSuitesLocally(TestNG.java:1116)
	at org.testng.TestNG.run(TestNG.java:1024)
	at org.testng.remote.RemoteTestNG.run(RemoteTestNG.java:112)
	at org.testng.remote.RemoteTestNG.initAndRun(RemoteTestNG.java:205)
	at org.testng.remote.RemoteTestNG.main(RemoteTestNG.java:176)
]]>
    </error>
  </testcase> <!-- dependentTest -->
</testsuite> <!-- testcase.Demo -->
